Traceback (most recent call last):
  File "/opt/hostedtoolcache/Python/3.7.13/x64/lib/python3.7/site-packages/jupyter_cache/executors/utils.py", line 56, in single_nb_execution
    record_timing=False,
  File "/opt/hostedtoolcache/Python/3.7.13/x64/lib/python3.7/site-packages/nbclient/client.py", line 1204, in execute
    return NotebookClient(nb=nb, resources=resources, km=km, **kwargs).execute()
  File "/opt/hostedtoolcache/Python/3.7.13/x64/lib/python3.7/site-packages/nbclient/util.py", line 84, in wrapped
    return just_run(coro(*args, **kwargs))
  File "/opt/hostedtoolcache/Python/3.7.13/x64/lib/python3.7/site-packages/nbclient/util.py", line 62, in just_run
    return loop.run_until_complete(coro)
  File "/opt/hostedtoolcache/Python/3.7.13/x64/lib/python3.7/asyncio/base_events.py", line 587, in run_until_complete
    return future.result()
  File "/opt/hostedtoolcache/Python/3.7.13/x64/lib/python3.7/site-packages/nbclient/client.py", line 664, in async_execute
    cell, index, execution_count=self.code_cells_executed + 1
  File "/opt/hostedtoolcache/Python/3.7.13/x64/lib/python3.7/site-packages/nbclient/client.py", line 965, in async_execute_cell
    await self._check_raise_for_error(cell, cell_index, exec_reply)
  File "/opt/hostedtoolcache/Python/3.7.13/x64/lib/python3.7/site-packages/nbclient/client.py", line 862, in _check_raise_for_error
    raise CellExecutionError.from_cell_and_msg(cell, exec_reply_content)
nbclient.exceptions.CellExecutionError: An error occurred while executing the following cell:
------------------
from datascience import *

# import for plotting
%matplotlib inline
import matplotlib.pyplot as plots
plots.style.use('fivethirtyeight')
# Fix for datascience plots
import collections as collections
import collections.abc as abc
collections.Iterable = abc.Iterable
------------------

[0;31m---------------------------------------------------------------------------[0m
[0;31mModuleNotFoundError[0m                       Traceback (most recent call last)
[0;32m/tmp/ipykernel_1814/3627246204.py[0m in [0;36m<module>[0;34m[0m
[0;32m----> 1[0;31m [0;32mfrom[0m [0mdatascience[0m [0;32mimport[0m [0;34m*[0m[0;34m[0m[0;34m[0m[0m
[0m[1;32m      2[0m [0;34m[0m[0m
[1;32m      3[0m [0;31m# import for plotting[0m[0;34m[0m[0;34m[0m[0;34m[0m[0m
[1;32m      4[0m [0mget_ipython[0m[0;34m([0m[0;34m)[0m[0;34m.[0m[0mrun_line_magic[0m[0;34m([0m[0;34m'matplotlib'[0m[0;34m,[0m [0;34m'inline'[0m[0;34m)[0m[0;34m[0m[0;34m[0m[0m
[1;32m      5[0m [0;32mimport[0m [0mmatplotlib[0m[0;34m.[0m[0mpyplot[0m [0;32mas[0m [0mplots[0m[0;34m[0m[0;34m[0m[0m

[0;31mModuleNotFoundError[0m: No module named 'datascience'
ModuleNotFoundError: No module named 'datascience'

